<?xml version="1.0" encoding="utf-8" ?>
<!-- =================================================================================== -->
<!-- |    This document was autogenerated by xacro from /home/henry/ROS/simulation_ws/src/simulation/robotarm_description/urdf/robotarm.xacro | -->
<!-- |    EDITING THIS FILE BY HAND IS NOT RECOMMENDED                                 | -->
<!-- =================================================================================== -->
<robot name="robotarm">
    <material name="silver">
        <color rgba="0.700 0.700 0.700 1.000" />
    </material>
    <material name="black">
        <color rgba="0.0 0.0 0.0 1.0" />
    </material>
    <material name="blue">
        <color rgba="0.0 0.0 0.8 1.0" />
    </material>
    <material name="green">
        <color rgba="0.0 1.0 0.0 1.0" />
    </material>
    <material name="grey">
        <color rgba="0.4 0.4 0.4 1.0" />
    </material>
    <material name="orange">
        <color rgba="1.0 0.423529411765 0.0392156862745 1.0" />
    </material>
    <material name="brown">
        <color rgba="0.870588235294 0.811764705882 0.764705882353 1.0" />
    </material>
    <material name="red">
        <color rgba="0.4 0.2 0.2 1.0" />
    </material>
    <material name="white">
        <color rgba="0.8 0.8 0.8 1.0" />
    </material>
    <transmission name="joint_1_tran">
        <type>transmission_interface/SimpleTransmission</type>
        <joint name="joint_1">
            <hardwareInterface>hardware_interface/PositionJointInterface</hardwareInterface>
        </joint>
        <actuator name="joint_1_actr">
            <hardwareInterface>hardware_interface/PositionJointInterface</hardwareInterface>
            <mechanicalReduction>1</mechanicalReduction>
        </actuator>
    </transmission>
    <transmission name="joint_2_tran">
        <type>transmission_interface/SimpleTransmission</type>
        <joint name="joint_2">
            <hardwareInterface>hardware_interface/PositionJointInterface</hardwareInterface>
        </joint>
        <actuator name="joint_2_actr">
            <hardwareInterface>hardware_interface/PositionJointInterface</hardwareInterface>
            <mechanicalReduction>1</mechanicalReduction>
        </actuator>
    </transmission>
    <transmission name="joint_3_tran">
        <type>transmission_interface/SimpleTransmission</type>
        <joint name="joint_3">
            <hardwareInterface>hardware_interface/PositionJointInterface</hardwareInterface>
        </joint>
        <actuator name="joint_3_actr">
            <hardwareInterface>hardware_interface/PositionJointInterface</hardwareInterface>
            <mechanicalReduction>1</mechanicalReduction>
        </actuator>
    </transmission>
    <transmission name="joint_4_tran">
        <type>transmission_interface/SimpleTransmission</type>
        <joint name="joint_4">
            <hardwareInterface>hardware_interface/PositionJointInterface</hardwareInterface>
        </joint>
        <actuator name="joint_4_actr">
            <hardwareInterface>hardware_interface/PositionJointInterface</hardwareInterface>
            <mechanicalReduction>1</mechanicalReduction>
        </actuator>
    </transmission>
    <transmission name="joint_5_tran">
        <type>transmission_interface/SimpleTransmission</type>
        <joint name="joint_5">
            <hardwareInterface>hardware_interface/PositionJointInterface</hardwareInterface>
        </joint>
        <actuator name="joint_5_actr">
            <hardwareInterface>hardware_interface/PositionJointInterface</hardwareInterface>
            <mechanicalReduction>1</mechanicalReduction>
        </actuator>
    </transmission>
    <transmission name="joint_6_tran">
        <type>transmission_interface/SimpleTransmission</type>
        <joint name="joint_6">
            <hardwareInterface>hardware_interface/PositionJointInterface</hardwareInterface>
        </joint>
        <actuator name="joint_6_actr">
            <hardwareInterface>hardware_interface/PositionJointInterface</hardwareInterface>
            <mechanicalReduction>1</mechanicalReduction>
        </actuator>
    </transmission>
    <gazebo>
        <plugin filename="libgazebo_ros_control.so" name="control" />
    </gazebo>
    <gazebo reference="base_link">
        <material>Gazebo/Black</material>
        <mu1>0.2</mu1>
        <mu2>0.2</mu2>
        <selfCollide>true</selfCollide>
        <gravity>true</gravity>
    </gazebo>
    <gazebo reference="link_1_1">
        <material>Gazebo/Grey</material>
        <mu1>0.2</mu1>
        <mu2>0.2</mu2>
        <selfCollide>true</selfCollide>
    </gazebo>
    <gazebo reference="link_2_1">
        <material>Gazebo/Black</material>
        <mu1>0.2</mu1>
        <mu2>0.2</mu2>
        <selfCollide>true</selfCollide>
    </gazebo>
    <gazebo reference="link_3_1">
        <material>Gazebo/Grey</material>
        <mu1>0.2</mu1>
        <mu2>0.2</mu2>
        <selfCollide>true</selfCollide>
    </gazebo>
    <gazebo reference="link_4_1">
        <material>$Gazebo/White</material>
        <mu1>0.2</mu1>
        <mu2>0.2</mu2>
        <selfCollide>true</selfCollide>
    </gazebo>
    <gazebo reference="link_5_1">
        <material>Gazebo/Grey</material>
        <mu1>0.2</mu1>
        <mu2>0.2</mu2>
        <selfCollide>true</selfCollide>
    </gazebo>
    <gazebo reference="link_6_1">
        <material>Gazebo/White</material>
        <mu1>0.2</mu1>
        <mu2>0.2</mu2>
        <selfCollide>true</selfCollide>
    </gazebo>
    <gazebo reference="link_7_1">
        <material>Gazebo/Grey</material>
        <mu1>0.2</mu1>
        <mu2>0.2</mu2>
        <selfCollide>true</selfCollide>
    </gazebo>
    <gazebo reference="link_8_1">
        <material>Gazebo/Black</material>
        <mu1>0.2</mu1>
        <mu2>0.2</mu2>
        <selfCollide>true</selfCollide>
    </gazebo>
    <gazebo reference="link_9_1">
        <material>Gazebo/White</material>
        <mu1>0.2</mu1>
        <mu2>0.2</mu2>
        <selfCollide>true</selfCollide>
    </gazebo>
    <gazebo reference="link_10_1">
        <material>Gazebo/Black</material>
        <mu1>0.2</mu1>
        <mu2>0.2</mu2>
        <selfCollide>true</selfCollide>
    </gazebo>
    <gazebo reference="link_11_1">
        <material>Gazebo/White</material>
        <mu1>0.2</mu1>
        <mu2>0.2</mu2>
        <selfCollide>true</selfCollide>
    </gazebo>
    <gazebo reference="link_12_1">
        <material>Gazebo/Grey</material>
        <mu1>0.2</mu1>
        <mu2>0.2</mu2>
        <selfCollide>true</selfCollide>
    </gazebo>
    <gazebo reference="link_13_1">
        <material>Gazebo/Black</material>
        <mu1>0.2</mu1>
        <mu2>0.2</mu2>
        <selfCollide>true</selfCollide>
    </gazebo>
    <gazebo reference="grabber_1">
        <material>Gazebo/Grey</material>
        <mu1>0.2</mu1>
        <mu2>0.2</mu2>
        <selfCollide>true</selfCollide>
    </gazebo>
    <link name="base_link">
        
<inertial>
            <origin rpy="0 0 0" xyz="0.3027889997472169 0.10052323881558602 -0.5238589999999963" />
            <mass value="0.5695940432953642" />
            <inertia ixx="0.003709" ixy="-0.0" ixz="0.0" iyy="0.003816" iyz="0.0" izz="0.007522" />
        </inertial>

        <visual>
            <origin rpy="0 0 0" xyz="0 0 0" />
            <geometry>
                <mesh filename="package://robotarm_description/meshes/base_link.stl" scale="0.001 0.001 0.001" />
            </geometry>
            <material name="black" />
        </visual>
        <collision>
            <origin rpy="0 0 0" xyz="0 0 0" />
            <geometry>
                <mesh filename="package://robotarm_description/meshes/base_link.stl" scale="0.001 0.001 0.001" />
            </geometry>
        </collision>
    </link>
    <link name="link_1_1">
        
<inertial>
            <origin rpy="0 0 0" xyz="-1.8697871029260682e-10 0.004753535232433076 0.03231546386634754" />
            <mass value="0.986632768311051" />
            <inertia ixx="0.001937" ixy="-0.0" ixz="-0.0" iyy="0.002238" iyz="4.5e-05" izz="0.003229" />
        </inertial>

        <visual>
            <origin rpy="0 0 0" xyz="-0.302789 -0.114578 0.520859" />
            <geometry>
                <mesh filename="package://robotarm_description/meshes/link_1_1.stl" scale="0.001 0.001 0.001" />
            </geometry>
            <material name="grey" />
        </visual>
        <collision>
            <origin rpy="0 0 0" xyz="-0.302789 -0.114578 0.520859" />
            <geometry>
                <mesh filename="package://robotarm_description/meshes/link_1_1.stl" scale="0.001 0.001 0.001" />
            </geometry>
        </collision>
    </link>
    <link name="link_2_1">
        
<inertial>
            <origin rpy="0 0 0" xyz="-1.8688406377975753e-10 -4.917767099238413e-07 0.011643712562816266" />
            <mass value="0.1359095393443759" />
            <inertia ixx="1.6e-05" ixy="0.0" ixz="-0.0" iyy="1.6e-05" iyz="0.0" izz="1.9e-05" />
        </inertial>

        <visual>
            <origin rpy="0 0 0" xyz="-0.302789 -0.114578 0.460859" />
            <geometry>
                <mesh filename="package://robotarm_description/meshes/link_2_1.stl" scale="0.001 0.001 0.001" />
            </geometry>
            <material name="black" />
        </visual>
        <collision>
            <origin rpy="0 0 0" xyz="-0.302789 -0.114578 0.460859" />
            <geometry>
                <mesh filename="package://robotarm_description/meshes/link_2_1.stl" scale="0.001 0.001 0.001" />
            </geometry>
        </collision>
    </link>
    <link name="link_3_1">
        
<inertial>
            <origin rpy="0 0 0" xyz="3.457651543831153e-05 -5.149846274699055e-07 0.038555020607762114" />
            <mass value="0.734301344058547" />
            <inertia ixx="0.000886" ixy="0.0" ixz="4e-06" iyy="0.0011" iyz="0.0" izz="0.000593" />
        </inertial>

        <visual>
            <origin rpy="0 0 0" xyz="-0.302789 -0.114578 0.436859" />
            <geometry>
                <mesh filename="package://robotarm_description/meshes/link_3_1.stl" scale="0.001 0.001 0.001" />
            </geometry>
            <material name="grey" />
        </visual>
        <collision>
            <origin rpy="0 0 0" xyz="-0.302789 -0.114578 0.436859" />
            <geometry>
                <mesh filename="package://robotarm_description/meshes/link_3_1.stl" scale="0.001 0.001 0.001" />
            </geometry>
        </collision>
    </link>
    <link name="link_4_1">
        
<inertial>
            <origin rpy="0 0 0" xyz="0.0014999998130816317 -4.917794316078306e-07 -5.14804865403562e-12" />
            <mass value="0.0015536746468328695" />
            <inertia ixx="0.0" ixy="-0.0" ixz="-0.0" iyy="0.0" iyz="-0.0" izz="0.0" />
        </inertial>

        <visual>
            <origin rpy="0 0 0" xyz="-0.278789 -0.114578 0.358359" />
            <geometry>
                <mesh filename="package://robotarm_description/meshes/link_4_1.stl" scale="0.001 0.001 0.001" />
            </geometry>
            <material name="white" />
        </visual>
        <collision>
            <origin rpy="0 0 0" xyz="-0.278789 -0.114578 0.358359" />
            <geometry>
                <mesh filename="package://robotarm_description/meshes/link_4_1.stl" scale="0.001 0.001 0.001" />
            </geometry>
        </collision>
    </link>
    <link name="link_5_1">
        
<inertial>
            <origin rpy="0 0 0" xyz="0.02074999941017852 2.555022859669631e-05 0.08450695857811241" />
            <mass value="0.18341801530628282" />
            <inertia ixx="0.000814" ixy="0.0" ixz="-0.0" iyy="0.00083" iyz="-0.0" izz="8.3e-05" />
        </inertial>

        <visual>
            <origin rpy="0 0 0" xyz="-0.281789 -0.114578 0.358359" />
            <geometry>
                <mesh filename="package://robotarm_description/meshes/link_5_1.stl" scale="0.001 0.001 0.001" />
            </geometry>
            <material name="grey" />
        </visual>
        <collision>
            <origin rpy="0 0 0" xyz="-0.281789 -0.114578 0.358359" />
            <geometry>
                <mesh filename="package://robotarm_description/meshes/link_5_1.stl" scale="0.001 0.001 0.001" />
            </geometry>
        </collision>
    </link>
    <link name="link_6_1">
        
<inertial>
            <origin rpy="0 0 0" xyz="0.0014999998130840186 -4.917651367092324e-07 -3.824804362118073e-11" />
            <mass value="0.0015536746468328695" />
            <inertia ixx="0.0" ixy="-0.0" ixz="-0.0" iyy="0.0" iyz="-0.0" izz="0.0" />
        </inertial>

        <visual>
            <origin rpy="0 0 0" xyz="-0.287789 -0.114578 0.178359" />
            <geometry>
                <mesh filename="package://robotarm_description/meshes/link_6_1.stl" scale="0.001 0.001 0.001" />
            </geometry>
            <material name="white" />
        </visual>
        <collision>
            <origin rpy="0 0 0" xyz="-0.287789 -0.114578 0.178359" />
            <geometry>
                <mesh filename="package://robotarm_description/meshes/link_6_1.stl" scale="0.001 0.001 0.001" />
            </geometry>
        </collision>
    </link>
    <link name="link_7_1">
        
<inertial>
            <origin rpy="0 0 0" xyz="0.011710659258666545 0.050456556016627865 0.0013142964981744387" />
            <mass value="0.08989065409828118" />
            <inertia ixx="0.000181" ixy="-1e-06" ixz="-0.0" iyy="2.9e-05" iyz="-4e-06" izz="0.000171" />
        </inertial>

        <visual>
            <origin rpy="0 0 0" xyz="-0.290789 -0.114578 0.178359" />
            <geometry>
                <mesh filename="package://robotarm_description/meshes/link_7_1.stl" scale="0.001 0.001 0.001" />
            </geometry>
            <material name="grey" />
        </visual>
        <collision>
            <origin rpy="0 0 0" xyz="-0.290789 -0.114578 0.178359" />
            <geometry>
                <mesh filename="package://robotarm_description/meshes/link_7_1.stl" scale="0.001 0.001 0.001" />
            </geometry>
        </collision>
    </link>
    <link name="link_8_1">
        
<inertial>
            <origin rpy="0 0 0" xyz="-0.004750000186926617 -0.008056568949482312 -0.024648856253007" />
            <mass value="0.2407180144714228" />
            <inertia ixx="6.3e-05" ixy="-0.0" ixz="-0.0" iyy="4.2e-05" iyz="1e-06" izz="3.7e-05" />
        </inertial>

        <visual>
            <origin rpy="0 0 0" xyz="-0.307539 -0.237219 0.14375" />
            <geometry>
                <mesh filename="package://robotarm_description/meshes/link_8_1.stl" scale="0.001 0.001 0.001" />
            </geometry>
            <material name="black" />
        </visual>
        <collision>
            <origin rpy="0 0 0" xyz="-0.307539 -0.237219 0.14375" />
            <geometry>
                <mesh filename="package://robotarm_description/meshes/link_8_1.stl" scale="0.001 0.001 0.001" />
            </geometry>
        </collision>
    </link>
    <link name="link_9_1">
        
<inertial>
            <origin rpy="0 0 0" xyz="-0.007734910162193742 0.028870766333701725 2.1412395295739017e-07" />
            <mass value="0.15826451533791172" />
            <inertia ixx="9.7e-05" ixy="5e-06" ixz="-0.0" iyy="4e-05" iyz="0.0" izz="0.000108" />
        </inertial>

        <visual>
            <origin rpy="0 0 0" xyz="-0.302789 -0.258219 0.178359" />
            <geometry>
                <mesh filename="package://robotarm_description/meshes/link_9_1.stl" scale="0.001 0.001 0.001" />
            </geometry>
            <material name="white" />
        </visual>
        <collision>
            <origin rpy="0 0 0" xyz="-0.302789 -0.258219 0.178359" />
            <geometry>
                <mesh filename="package://robotarm_description/meshes/link_9_1.stl" scale="0.001 0.001 0.001" />
            </geometry>
        </collision>
    </link>
    <link name="link_10_1">
        
<inertial>
            <origin rpy="0 0 0" xyz="-0.008056178444775353 -0.0243514216477424 -0.004749786152630581" />
            <mass value="0.2407180144714228" />
            <inertia ixx="4.2e-05" ixy="-1e-06" ixz="0.0" iyy="3.7e-05" iyz="-0.0" izz="6.3e-05" />
        </inertial>

        <visual>
            <origin rpy="0 0 0" xyz="-0.314789 -0.321969 0.173359" />
            <geometry>
                <mesh filename="package://robotarm_description/meshes/link_10_1.stl" scale="0.001 0.001 0.001" />
            </geometry>
            <material name="black" />
        </visual>
        <collision>
            <origin rpy="0 0 0" xyz="-0.314789 -0.321969 0.173359" />
            <geometry>
                <mesh filename="package://robotarm_description/meshes/link_10_1.stl" scale="0.001 0.001 0.001" />
            </geometry>
        </collision>
    </link>
    <link name="link_11_1">
        
<inertial>
            <origin rpy="0 0 0" xyz="-0.029413719143845662 0.02892119873865162 0.0011736127180720646" />
            <mass value="0.39249068379170354" />
            <inertia ixx="0.000264" ixy="1.3e-05" ixz="2e-06" iyy="0.000282" iyz="-1.7e-05" izz="0.000382" />
        </inertial>

        <visual>
            <origin rpy="0 0 0" xyz="-0.335789 -0.307578 0.178109" />
            <geometry>
                <mesh filename="package://robotarm_description/meshes/link_11_1.stl" scale="0.001 0.001 0.001" />
            </geometry>
            <material name="white" />
        </visual>
        <collision>
            <origin rpy="0 0 0" xyz="-0.335789 -0.307578 0.178109" />
            <geometry>
                <mesh filename="package://robotarm_description/meshes/link_11_1.stl" scale="0.001 0.001 0.001" />
            </geometry>
        </collision>
    </link>
    <link name="link_12_1">
        
<inertial>
            <origin rpy="0 0 0" xyz="-0.004749226546193808 -0.008056670005938016 -0.02464885625438537" />
            <mass value="0.24071801447142827" />
            <inertia ixx="6.3e-05" ixy="-0.0" ixz="0.0" iyy="4.2e-05" iyz="1e-06" izz="3.7e-05" />
        </inertial>

        <visual>
            <origin rpy="0 0 0" xyz="-0.307538 -0.375732 0.1435" />
            <geometry>
                <mesh filename="package://robotarm_description/meshes/link_12_1.stl" scale="0.001 0.001 0.001" />
            </geometry>
            <material name="black" />
        </visual>
        <collision>
            <origin rpy="0 0 0" xyz="-0.307538 -0.375732 0.1435" />
            <geometry>
                <mesh filename="package://robotarm_description/meshes/link_12_1.stl" scale="0.001 0.001 0.001" />
            </geometry>
        </collision>
    </link>
    <link name="link_13_1">
        
<inertial>
            <origin rpy="0 0 0" xyz="-2.7483151865403954e-09 0.0029995082518860516 3.0996027545193705e-05" />
            <mass value="0.012367021038363606" />
            <inertia ixx="2e-06" ixy="-0.0" ixz="-0.0" iyy="4e-06" iyz="0.0" izz="2e-06" />
        </inertial>

        <visual>
            <origin rpy="0 0 0" xyz="-0.302789 -0.396732 0.178109" />
            <geometry>
                <mesh filename="package://robotarm_description/meshes/link_13_1.stl" scale="0.001 0.001 0.001" />
            </geometry>
            <material name="black" />
        </visual>
        <collision>
            <origin rpy="0 0 0" xyz="-0.302789 -0.396732 0.178109" />
            <geometry>
                <mesh filename="package://robotarm_description/meshes/link_13_1.stl" scale="0.001 0.001 0.001" />
            </geometry>
        </collision>
    </link>
    <link name="grabber_1">
        
<inertial>
            <origin rpy="0 0 0" xyz="-0.008103951685665245 0.055697789484993654 -0.007903234107681345" />
            <mass value="0.23807227969898195" />
            <inertia ixx="0.000186" ixy="2e-06" ixz="-0.0" iyy="0.000212" iyz="-0.0" izz="0.000388" />
        </inertial>

        <visual>
            <origin rpy="0 0 0" xyz="-0.310789 -0.402732 0.170109" />
            <geometry>
                <mesh filename="package://robotarm_description/meshes/grabber_1.stl" scale="0.001 0.001 0.001" />
            </geometry>
            <material name="silver" />
        </visual>
        <collision>
            <origin rpy="0 0 0" xyz="-0.310789 -0.402732 0.170109" />
            <geometry>
                <mesh filename="package://robotarm_description/meshes/grabber_1.stl" scale="0.001 0.001 0.001" />
            </geometry>
        </collision>
    </link>
    <joint name="Rigid1" type="fixed">
        <origin rpy="0 0 0" xyz="0.302789 0.114578 -0.520859" />
        <parent link="base_link" />
        <child link="link_1_1" />
    </joint>
    <joint name="Rigid2" type="fixed">
        <origin rpy="0 0 0" xyz="0.0 0.0 0.06" />
        <parent link="link_1_1" />
        <child link="link_2_1" />
    </joint>
    <joint name="joint_1" type="continuous">
        <origin rpy="0 0 0" xyz="0.0 0.0 0.024" />
        <parent link="link_2_1" />
        <child link="link_3_1" />
        <axis xyz="0.0 0.0 1.0" />
    </joint>
    <joint name="Rigid4" type="fixed">
        <origin rpy="0 0 0" xyz="-0.024 0.0 0.0785" />
        <parent link="link_3_1" />
        <child link="link_4_1" />
    </joint>
    <joint name="joint_2" type="continuous">
        <origin rpy="0 0 0" xyz="0.003 0.0 0.0" />
        <parent link="link_4_1" />
        <child link="link_5_1" />
        <axis xyz="1.0 0.0 -0.0" />
    </joint>
    <joint name="Rigid6" type="fixed">
        <origin rpy="0 0 0" xyz="0.006 0.0 0.18" />
        <parent link="link_5_1" />
        <child link="link_6_1" />
    </joint>
    <joint name="joint_3" type="continuous">
        <origin rpy="0 0 0" xyz="0.003 0.0 0.0" />
        <parent link="link_6_1" />
        <child link="link_7_1" />
        <axis xyz="1.0 0.0 -0.0" />
    </joint>
    <joint name="Rigid8" type="fixed">
        <origin rpy="0 0 0" xyz="0.01675 0.122641 0.034609" />
        <parent link="link_7_1" />
        <child link="link_8_1" />
    </joint>
    <joint name="joint_4" type="continuous">
        <origin rpy="0 0 0" xyz="-0.00475 0.021 -0.034609" />
        <parent link="link_8_1" />
        <child link="link_9_1" />
        <axis xyz="-0.0 1.0 0.0" />
    </joint>
    <joint name="Rigid10" type="fixed">
        <origin rpy="0 0 0" xyz="0.012 0.06375 0.005" />
        <parent link="link_9_1" />
        <child link="link_10_1" />
    </joint>
    <joint name="joint_5" type="continuous">
        <origin rpy="0 0 0" xyz="0.021 -0.014391 -0.00475" />
        <parent link="link_10_1" />
        <child link="link_11_1" />
        <axis xyz="1.0 -0.0 -0.0" />
    </joint>
    <joint name="Rigid12" type="fixed">
        <origin rpy="0 0 0" xyz="-0.028251 0.068154 0.034609" />
        <parent link="link_11_1" />
        <child link="link_12_1" />
    </joint>
    <joint name="joint_6" type="continuous">
        <origin rpy="0 0 0" xyz="-0.004749 0.021 -0.034609" />
        <parent link="link_12_1" />
        <child link="link_13_1" />
        <axis xyz="0.0 1.0 0.0" />
    </joint>
    <joint name="Rigid14" type="fixed">
        <origin rpy="0 0 0" xyz="0.008 0.006 0.008" />
        <parent link="link_13_1" />
        <child link="grabber_1" />
    </joint>


</robot>
